2024-09-30 01:49:16,538 INFO:C:\Users\27740\OneDrive\Documents\FinGPT\Github\fingpt_rcos\ChatBot-Fin\chat_server\chat_server_app\views.py changed, reloading.
2024-09-30 01:50:09,527 ERROR:Internal Server Error: /get_adv_response/
Traceback (most recent call last):
  File "C:\Users\27740\AppData\Local\Programs\Python\Python312\Lib\site-packages\django\core\handlers\exception.py", line 55, in inner
    response = get_response(request)
               ^^^^^^^^^^^^^^^^^^^^^
  File "C:\Users\27740\AppData\Local\Programs\Python\Python312\Lib\site-packages\django\core\handlers\base.py", line 197, in _get_response
    response = wrapped_callback(request, *callback_args, **callback_kwargs)
               ^^^^^^^^^^^^^^^^^^^^^^^^^^^^^^^^^^^^^^^^^^^^^^^^^^^^^^^^^^^^
  File "C:\Users\27740\AppData\Local\Programs\Python\Python312\Lib\site-packages\django\views\decorators\csrf.py", line 65, in _view_wrapper
    return view_func(request, *args, **kwargs)
           ^^^^^^^^^^^^^^^^^^^^^^^^^^^^^^^^^^^
  File "C:\Users\27740\OneDrive\Documents\FinGPT\Github\fingpt_rcos\ChatBot-Fin\chat_server\chat_server_app\views.py", line 87, in adv_response
    responses[model] = ds.create_rag_advanced_response(question, message_list.copy(), model)
                       ^^^^^^^^^^^^^^^^^^^^^^^^^^^^^^^^^^^^^^^^^^^^^^^^^^^^^^^^^^^^^^^^^^^^^
  File "C:\Users\27740\OneDrive\Documents\FinGPT\Github\fingpt_rcos\ChatBot-Fin\chat_server\datascraper\datascraper.py", line 120, in create_rag_advanced_response
    response = cdm_rag.get_rag_advanced_response(user_input, model)
               ^^^^^^^^^^^^^^^^^^^^^^^^^^^^^^^^^^^^^^^^^^^^^^^^^^^^
  File "C:\Users\27740\OneDrive\Documents\FinGPT\Github\fingpt_rcos\ChatBot-Fin\chat_server\datascraper\cdm_rag.py", line 405, in get_rag_advanced_response
    return get_rag_response(question, model_name)
           ^^^^^^^^^^^^^^^^^^^^^^^^^^^^^^^^^^^^^^
  File "C:\Users\27740\OneDrive\Documents\FinGPT\Github\fingpt_rcos\ChatBot-Fin\chat_server\datascraper\cdm_rag.py", line 393, in get_rag_response
    relevant_chunks = retrieve_chunks(question, index, embeddings)
                      ^^^^^^^^^^^^^^^^^^^^^^^^^^^^^^^^^^^^^^^^^^^^
  File "C:\Users\27740\OneDrive\Documents\FinGPT\Github\fingpt_rcos\ChatBot-Fin\chat_server\datascraper\cdm_rag.py", line 341, in retrieve_chunks
    query_embedding = embed_query(query)
                      ^^^^^^^^^^^^^^^^^^
  File "C:\Users\27740\OneDrive\Documents\FinGPT\Github\fingpt_rcos\ChatBot-Fin\chat_server\datascraper\cdm_rag.py", line 331, in embed_query
    response = openai.Embedding.create(
               ^^^^^^^^^^^^^^^^^^^^^^^^
  File "C:\Users\27740\AppData\Local\Programs\Python\Python312\Lib\site-packages\openai\api_resources\embedding.py", line 33, in create
    response = super().create(*args, **kwargs)
               ^^^^^^^^^^^^^^^^^^^^^^^^^^^^^^^
  File "C:\Users\27740\AppData\Local\Programs\Python\Python312\Lib\site-packages\openai\api_resources\abstract\engine_api_resource.py", line 149, in create
    ) = cls.__prepare_create_request(
        ^^^^^^^^^^^^^^^^^^^^^^^^^^^^^
  File "C:\Users\27740\AppData\Local\Programs\Python\Python312\Lib\site-packages\openai\api_resources\abstract\engine_api_resource.py", line 106, in __prepare_create_request
    requestor = api_requestor.APIRequestor(
                ^^^^^^^^^^^^^^^^^^^^^^^^^^^
  File "C:\Users\27740\AppData\Local\Programs\Python\Python312\Lib\site-packages\openai\api_requestor.py", line 138, in __init__
    self.api_key = key or util.default_api_key()
                          ^^^^^^^^^^^^^^^^^^^^^^
  File "C:\Users\27740\AppData\Local\Programs\Python\Python312\Lib\site-packages\openai\util.py", line 186, in default_api_key
    raise openai.error.AuthenticationError(
openai.error.AuthenticationError: No API key provided. You can set your API key in code using 'openai.api_key = <API-KEY>', or you can set the environment variable OPENAI_API_KEY=<API-KEY>). If your API key is stored in a file, you can point the openai module at it with 'openai.api_key_path = <PATH>'. You can generate API keys in the OpenAI web interface. See https://platform.openai.com/account/api-keys for details.
2024-09-30 01:52:08,266 INFO:C:\Users\27740\OneDrive\Documents\FinGPT\Github\fingpt_rcos\ChatBot-Fin\chat_server\datascraper\cdm_rag.py changed, reloading.
2024-09-30 01:52:38,280 INFO:C:\Users\27740\OneDrive\Documents\FinGPT\Github\fingpt_rcos\ChatBot-Fin\chat_server\datascraper\cdm_rag.py changed, reloading.
2024-09-30 01:53:12,432 ERROR:Internal Server Error: /get_adv_response/
Traceback (most recent call last):
  File "C:\Users\27740\AppData\Local\Programs\Python\Python312\Lib\site-packages\django\core\handlers\exception.py", line 55, in inner
    response = get_response(request)
               ^^^^^^^^^^^^^^^^^^^^^
  File "C:\Users\27740\AppData\Local\Programs\Python\Python312\Lib\site-packages\django\core\handlers\base.py", line 197, in _get_response
    response = wrapped_callback(request, *callback_args, **callback_kwargs)
               ^^^^^^^^^^^^^^^^^^^^^^^^^^^^^^^^^^^^^^^^^^^^^^^^^^^^^^^^^^^^
  File "C:\Users\27740\AppData\Local\Programs\Python\Python312\Lib\site-packages\django\views\decorators\csrf.py", line 65, in _view_wrapper
    return view_func(request, *args, **kwargs)
           ^^^^^^^^^^^^^^^^^^^^^^^^^^^^^^^^^^^
  File "C:\Users\27740\OneDrive\Documents\FinGPT\Github\fingpt_rcos\ChatBot-Fin\chat_server\chat_server_app\views.py", line 87, in adv_response
    responses[model] = ds.create_rag_advanced_response(question, message_list.copy(), model)
                       ^^^^^^^^^^^^^^^^^^^^^^^^^^^^^^^^^^^^^^^^^^^^^^^^^^^^^^^^^^^^^^^^^^^^^
  File "C:\Users\27740\OneDrive\Documents\FinGPT\Github\fingpt_rcos\ChatBot-Fin\chat_server\datascraper\datascraper.py", line 120, in create_rag_advanced_response
    response = cdm_rag.get_rag_advanced_response(user_input, model)
               ^^^^^^^^^^^^^^^^^^^^^^^^^^^^^^^^^^^^^^^^^^^^^^^^^^^^
  File "C:\Users\27740\OneDrive\Documents\FinGPT\Github\fingpt_rcos\ChatBot-Fin\chat_server\datascraper\cdm_rag.py", line 405, in get_rag_advanced_response
    return get_rag_response(question, model_name)
           ^^^^^^^^^^^^^^^^^^^^^^^^^^^^^^^^^^^^^^
  File "C:\Users\27740\OneDrive\Documents\FinGPT\Github\fingpt_rcos\ChatBot-Fin\chat_server\datascraper\cdm_rag.py", line 393, in get_rag_response
    relevant_chunks = retrieve_chunks(question, index, embeddings)
                      ^^^^^^^^^^^^^^^^^^^^^^^^^^^^^^^^^^^^^^^^^^^^
  File "C:\Users\27740\OneDrive\Documents\FinGPT\Github\fingpt_rcos\ChatBot-Fin\chat_server\datascraper\cdm_rag.py", line 346, in retrieve_chunks
    distances, indices = index.search(query_vector, k)
                         ^^^^^^^^^^^^
AttributeError: 'NoneType' object has no attribute 'search'
2024-09-30 01:56:17,947 INFO:C:\Users\27740\OneDrive\Documents\FinGPT\Github\fingpt_rcos\ChatBot-Fin\chat_server\datascraper\cdm_rag.py changed, reloading.
2024-09-30 01:56:45,708 INFO:C:\Users\27740\OneDrive\Documents\FinGPT\Github\fingpt_rcos\ChatBot-Fin\chat_server\datascraper\cdm_rag.py changed, reloading.
2024-09-30 01:57:13,788 INFO:C:\Users\27740\OneDrive\Documents\FinGPT\Github\fingpt_rcos\ChatBot-Fin\chat_server\datascraper\datascraper.py changed, reloading.
2024-09-30 01:57:51,811 ERROR:The following file(s) are missing: faiss_index.idx, embeddings.pkl. Please ensure they are present.
2024-09-30 01:57:51,812 ERROR:The following file(s) are missing: faiss_index.idx, embeddings.pkl. Please ensure they are present.
2024-09-30 02:01:15,610 INFO:C:\Users\27740\OneDrive\Documents\FinGPT\Github\fingpt_rcos\ChatBot-Fin\chat_server\datascraper\cdm_rag.py changed, reloading.
2024-09-30 02:01:25,700 INFO:C:\Users\27740\OneDrive\Documents\FinGPT\Github\fingpt_rcos\ChatBot-Fin\chat_server\datascraper\cdm_rag.py changed, reloading.
2024-09-30 02:03:05,545 ERROR:Internal Server Error: /get_adv_response/
Traceback (most recent call last):
  File "C:\Users\27740\AppData\Local\Programs\Python\Python312\Lib\site-packages\django\core\handlers\exception.py", line 55, in inner
    response = get_response(request)
               ^^^^^^^^^^^^^^^^^^^^^
  File "C:\Users\27740\AppData\Local\Programs\Python\Python312\Lib\site-packages\django\core\handlers\base.py", line 197, in _get_response
    response = wrapped_callback(request, *callback_args, **callback_kwargs)
               ^^^^^^^^^^^^^^^^^^^^^^^^^^^^^^^^^^^^^^^^^^^^^^^^^^^^^^^^^^^^
  File "C:\Users\27740\AppData\Local\Programs\Python\Python312\Lib\site-packages\django\views\decorators\csrf.py", line 65, in _view_wrapper
    return view_func(request, *args, **kwargs)
           ^^^^^^^^^^^^^^^^^^^^^^^^^^^^^^^^^^^
  File "C:\Users\27740\OneDrive\Documents\FinGPT\Github\fingpt_rcos\ChatBot-Fin\chat_server\chat_server_app\views.py", line 87, in adv_response
    responses[model] = ds.create_rag_advanced_response(question, message_list.copy(), model)
                       ^^^^^^^^^^^^^^^^^^^^^^^^^^^^^^^^^^^^^^^^^^^^^^^^^^^^^^^^^^^^^^^^^^^^^
  File "C:\Users\27740\OneDrive\Documents\FinGPT\Github\fingpt_rcos\ChatBot-Fin\chat_server\datascraper\datascraper.py", line 127, in create_rag_advanced_response
    response = cdm_rag.get_rag_advanced_response(user_input, model)
               ^^^^^^^^^^^^^^^^^^^^^^^^^^^^^^^^^^^^^^^^^^^^^^^^^^^^
  File "C:\Users\27740\OneDrive\Documents\FinGPT\Github\fingpt_rcos\ChatBot-Fin\chat_server\datascraper\cdm_rag.py", line 139, in get_rag_advanced_response
    return get_rag_response(question, model_name)
           ^^^^^^^^^^^^^^^^^^^^^^^^^^^^^^^^^^^^^^
  File "C:\Users\27740\OneDrive\Documents\FinGPT\Github\fingpt_rcos\ChatBot-Fin\chat_server\datascraper\cdm_rag.py", line 127, in get_rag_response
    relevant_chunks = retrieve_chunks(question, index, embeddings)
                      ^^^^^^^^^^^^^^^^^^^^^^^^^^^^^^^^^^^^^^^^^^^^
  File "C:\Users\27740\OneDrive\Documents\FinGPT\Github\fingpt_rcos\ChatBot-Fin\chat_server\datascraper\cdm_rag.py", line 80, in retrieve_chunks
    distances, indices = index.search(query_vector, k)
                         ^^^^^^^^^^^^^^^^^^^^^^^^^^^^^
  File "C:\Users\27740\AppData\Local\Programs\Python\Python312\Lib\site-packages\faiss\class_wrappers.py", line 329, in replacement_search
    assert d == self.d
           ^^^^^^^^^^^
AssertionError
2024-09-30 02:05:19,366 INFO:C:\Users\27740\OneDrive\Documents\FinGPT\Github\fingpt_rcos\ChatBot-Fin\chat_server\datascraper\cdm_rag.py changed, reloading.
2024-09-30 02:06:59,977 INFO:C:\Users\27740\OneDrive\Documents\FinGPT\Github\fingpt_rcos\ChatBot-Fin\chat_server\datascraper\cdm_rag.py changed, reloading.
2024-10-01 10:39:06,796 INFO:C:\Users\T2774\Documents\FinGPT\Github\fingpt_rcos\ChatBot-Fin\chat_server\datascraper\cdm_rag.py changed, reloading.
